<mujoco>
    <option gravity="0 0 -9.81" integrator="RK4" timestep="0.02">
        <flag energy="enable"/>
    </option>

    <statistic meansize="0.05" extent="2" center="0 2 0"/>

    <visual>
        <global elevation="-5"/>
    </visual>

    <worldbody>
        <light diffuse=".4 .4 .4" specular="0.1 0.1 0.1" pos="0 0 2.0" dir="0 0 -1" castshadow="false"/>
        <light directional="true" diffuse=".8 .8 .8" specular="0.2 0.2 0.2" pos="0 0 4" dir="0 0 -1"/>

        <site name="origin" pos="0 0 0.0" size=".01" rgba="1 0 0 1"/>

        <body name="mass" pos="0.0 0 0.4025">
            <joint name="mass" type="slide" axis="0 0 1" damping="3.0"/>
            <geom size=".02 .02 .02" type="box" mass="1"/>
            <site name="attachment" size=".01" pos="0 0 0"rgba="1 0 0 1"/>
        </body>
    </worldbody>

    <tendon>
        <spatial name="tendon" range="0.03 5" limited="true" frictionloss="0.0" stiffness="100" springlength=".5">
            <site site="origin"/>
            <site site="attachment"/>
        </spatial>
    </tendon>

    <sensor>
        <tendonpos tendon="tendon"/>
        <force name="mass" site="attachment"/>
    </sensor>

    <actuator>
		<motor ctrllimited="true" ctrlrange="-20 20" gear="2" joint="mass" name="slide"/>
	</actuator>
</mujoco>
